<?xml version="1.0" encoding="utf-8" standalone="yes" ?>
<rss version="2.0" xmlns:atom="http://www.w3.org/2005/Atom">
  <channel>
    <title>Posts on </title>
    <link>/posts/</link>
    <description>Recent content in Posts on </description>
    <generator>Hugo -- gohugo.io</generator>
    
	<atom:link href="/posts/index.xml" rel="self" type="application/rss+xml" />
    
    
    <item>
      <title>Handle error from setTimeout</title>
      <link>/posts/handle-error-from-settimeout/</link>
      <pubDate>Mon, 01 Jan 0001 00:00:00 +0000</pubDate>
      
      <guid>/posts/handle-error-from-settimeout/</guid>
      <description>This block of code does not work:
try { setTimeout(function () { throw new Error(&#39;error!&#39;); }, 300) } catch (e) { console.log(&#39;Caught error: &#39;, e) }  Functions scheduled to run with setTimeout are executed in the main loop, outside the scope of the block that originated them.
Therefore, to handle errors, change the order of try-catch and setTimeout, like this:
setTimeout(function () { try { throw new Error(&#39;error!&#39;); } catch (e) { console.</description>
    </item>
    
  </channel>
</rss>