<?xml version="1.0" encoding="utf-8" standalone="yes" ?>
<rss version="2.0" xmlns:atom="http://www.w3.org/2005/Atom">
  <channel>
    <title>GeeKoffee</title>
    <link>https://geekoffee.ml/</link>
    <description>Recent content on GeeKoffee</description>
    <generator>Hugo -- gohugo.io</generator>
    <language>en-us</language>
    <copyright>Â© 2019 Glauber Magalhaes.&amp;nbsp;&lt;a href=&#34;https://www.gnu.org/licenses/gpl-3.0.html&#34;&gt;Some rights reserved&lt;/a&gt;.</copyright>
    <lastBuildDate>Sat, 22 Jun 2019 00:00:00 +0000</lastBuildDate>
    
	<atom:link href="https://geekoffee.ml/index.xml" rel="self" type="application/rss+xml" />
    
    
    <item>
      <title>Handle error from setTimeout</title>
      <link>https://geekoffee.ml/posts/handle-error-from-settimeout/</link>
      <pubDate>Sat, 22 Jun 2019 00:00:00 +0000</pubDate>
      
      <guid>https://geekoffee.ml/posts/handle-error-from-settimeout/</guid>
      <description>This block of code does not work:
try { setTimeout(function () { throw new Error(&#39;error!&#39;); }, 300) } catch (e) { console.log(&#39;Caught error: &#39;, e) }  Functions scheduled to run with setTimeout are executed in the main loop, outside the scope of the block that originated them.
Therefore, to handle errors, change the order of try-catch and setTimeout, like this:
setTimeout(function () { try { throw new Error(&#39;error!&#39;); } catch (e) { console.</description>
    </item>
    
  </channel>
</rss>